<?xml version='1.0' encoding='UTF-8'?>
<robot name="ranger_air_description">
  <link name="base_link">
    <inertial>
      <origin xyz="-0.0269453553477971 4.88289151054452E-05 0.138776943804503" rpy="0 0 0" />
      <mass value="9.62557497725158" />
      <inertia ixx="0.0836578300249299" ixy="-0.00247163484979424" ixz="0.000109124201879488" iyy="0.0555064526888553" iyz="7.6528928799148E-07" izz="0.127512148927851" />
    </inertial>
    <visual>
      <origin xyz="0 0 0" rpy="0 0 0" />
      <geometry>
        <mesh filename="package://ranger_air_description/meshes/dae/base_link.dae" />
      </geometry>
      <material name="">
        <color rgba="0.792156862745098 0.819607843137255 0.933333333333333 1" />
      </material>
    </visual>
    <collision>
      <origin xyz="0 0 0" rpy="0 0 0" />
      <geometry>
        <mesh filename="package://ranger_air_description/meshes/dae/base_link.dae" />
      </geometry>
    </collision>
  </link>
  <link name="imu_link">
    <inertial>
      <origin xyz="-7.51173708920111E-05 7.51173708920406E-05 0.00149999999999999" rpy="0 0 0" />
      <mass value="0.000426" />
      <inertia ixx="5.32909624413146E-09" ixy="-1.72403755868542E-10" ixz="-2.56308956479191E-24" iyy="5.32909624413147E-09" iyz="-1.61090078229413E-23" izz="1.00191924882629E-08" />
    </inertial>
    <visual>
      <origin xyz="0 0 0" rpy="0 0 0" />
      <geometry>
        <mesh filename="package://ranger_air_description/meshes/imu_link.STL" />
      </geometry>
      <material name="">
        <color rgba="1 1 1 1" />
      </material>
    </visual>
    <collision>
      <origin xyz="0 0 0" rpy="0 0 0" />
      <geometry>
        <mesh filename="package://ranger_air_description/meshes/imu_link.STL" />
      </geometry>
    </collision>
  </link>
  <joint name="imu_joint" type="fixed">
    <origin xyz="-0.00269279932190335 0.117006197251626 0.172572605714962" rpy="1.5707963267949 -1.5707963267949 0" />
    <parent link="base_link" />
    <child link="imu_link" />
    <axis xyz="0 0 0" />
  </joint>
  <link name="front_lidar_link">
    <inertial>
      <origin xyz="-0.0024322542360638 -7.57434565393234E-06 -0.0156647798701829" rpy="0 0 0" />
      <mass value="0.0269222563572699" />
      <inertia ixx="9.62972066845586E-06" ixy="-6.69475455049995E-10" ixz="2.48281613499449E-08" iyy="9.64981682902064E-06" iyz="-1.43263267252535E-11" izz="1.74096865451407E-05" />
    </inertial>
    <visual>
      <origin xyz="0 0 0" rpy="0 0 0" />
      <geometry>
        <mesh filename="package://ranger_air_description/meshes/dae/front_lidar_link.dae" />
      </geometry>
      <material name="">
        <color rgba="1 1 1 1" />
      </material>
    </visual>
    <collision>
      <origin xyz="0 0 0" rpy="0 0 0" />
      <geometry>
        <mesh filename="package://ranger_air_description/meshes/front_lidar_link.STL" />
      </geometry>
    </collision>
  </link>
  <joint name="front_lidar_joint" type="fixed">
    <origin xyz="0.2 -0.175 0.268" rpy="0 0 -0.78539816339746" />
    <parent link="base_link" />
    <child link="front_lidar_link" />
    <axis xyz="0 0 0" />
  </joint>
  <link name="back_lidar_link">
    <inertial>
      <origin xyz="-0.00243225423607701 -7.57434566700521E-06 -0.0156647798701824" rpy="0 0 0" />
      <mass value="0.0269222563572854" />
      <inertia ixx="9.62972066845615E-06" ixy="-6.69475455080912E-10" ixz="2.4828161349934E-08" iyy="9.64981682902092E-06" iyz="-1.43263267611196E-11" izz="1.74096865451409E-05" />
    </inertial>
    <visual>
      <origin xyz="0 0 0" rpy="0 0 0" />
      <geometry>
        <mesh filename="package://ranger_air_description/meshes/dae/back_lidar_link.dae" />
      </geometry>
      <material name="">
        <color rgba="1 1 1 1" />
      </material>
    </visual>
    <collision>
      <origin xyz="0 0 0" rpy="0 0 0" />
      <geometry>
        <mesh filename="package://ranger_air_description/meshes/back_lidar_link.STL" />
      </geometry>
    </collision>
  </link>
  <joint name="back_lidar_joint" type="fixed">
    <origin xyz="-0.199999999999958 0.174999999999997 0.268" rpy="0 0 2.35619449019234" />
    <parent link="base_link" />
    <child link="back_lidar_link" />
    <axis xyz="0 0 0" />
  </joint>
  <link name="camera_link">
    <inertial>
      <origin xyz="-0.00781360439226064 -4.62643811109874E-05 0.00015691163838176" rpy="0 0 0" />
      <mass value="0.0189598021123256" />
      <inertia ixx="1.09290416951151E-05" ixy="5.74101407704989E-09" ixz="-2.17154464045429E-08" iyy="1.72930174582617E-06" iyz="-8.47818936297681E-09" izz="1.0379713403702E-05" />
    </inertial>
    <visual>
      <origin xyz="0 0 0" rpy="0 0 0" />
      <geometry>
        <mesh filename="package://ranger_air_description/meshes/dae/camera_link.dae" />
      </geometry>
      <material name="">
        <color rgba="1 1 1 1" />
      </material>
    </visual>
    <collision>
      <origin xyz="0 0 0" rpy="0 0 0" />
      <geometry>
        <mesh filename="package://ranger_air_description/meshes/dae/camera_link.dae" />
      </geometry>
    </collision>
  </link>
  <joint name="camera_joint" type="fixed">
    <origin xyz="0.264320690911 0 0.169753030571818" rpy="0 -0.139626340159547 0" />
    <parent link="base_link" />
    <child link="camera_link" />
    <axis xyz="0 0 0" />
  </joint>
  <link name="fl_steering_link">
    <inertial>
      <origin xyz="-4.41226727665167E-05 0.0157129719167315 0.00410410320602114" rpy="0 0 0" />
      <mass value="0.935307991635668" />
      <inertia ixx="0.00108568401565883" ixy="7.743516771268E-08" ixz="-2.33490054511026E-07" iyy="0.00106453940002428" iyz="-0.000235815859378652" izz="0.0012538948846579" />
    </inertial>
    <visual>
      <origin xyz="0 0 0" rpy="0 0 0" />
      <geometry>
        <mesh filename="package://ranger_air_description/meshes/dae/fl_streering_link.dae" />
      </geometry>
      <material name="">
        <color rgba="0.752941176470588 0.752941176470588 0.752941176470588 1" />
      </material>
    </visual>
    <collision>
      <origin xyz="0 0 0" rpy="0 0 0" />
      <geometry>
        <mesh filename="package://ranger_air_description/meshes/dae/fl_streering_link.dae" />
      </geometry>
    </collision>
  </link>
  <joint name="fl_steering_joint" type="continuous">
    <origin xyz="0.194 0.169 0.1355" rpy="-3.14159265358979 0 0" />
    <parent link="base_link" />
    <child link="fl_steering_link" />
    <axis xyz="0 0 -1" />
  </joint>
  <link name="fl_wheel_link">
    <inertial>
      <origin xyz="2.77555756156289E-17 2.77555756156289E-17 -0.000252801407574443" rpy="0 0 0" />
      <mass value="0.741126743204084" />
      <inertia ixx="0.000890769648192525" ixy="-5.4135978102862E-25" ixz="2.83258046844794E-20" iyy="0.000890761023713873" iyz="-4.04095046703963E-20" izz="0.00113190510709934" />
    </inertial>
    <visual>
      <origin xyz="0 0 0" rpy="0 0 0" />
      <geometry>
        <mesh filename="package://ranger_air_description/meshes/dae/fl_wheel_link.dae" />
      </geometry>
      <material name="">
        <color rgba="0.792156862745098 0.819607843137255 0.933333333333333 1" />
      </material>
    </visual>
    <collision>
      <origin xyz="0 0 0" rpy="0 0 0" />
      <geometry>
        <mesh filename="package://ranger_air_description/meshes/dae/fl_wheel_link.dae" />
      </geometry>
    </collision>
  </link>
  <joint name="fl_wheel_joint" type="continuous">
    <origin xyz="0 0 0.0749999999999999" rpy="1.5707963267949 0 0" />
    <parent link="fl_steering_link" />
    <child link="fl_wheel_link" />
    <axis xyz="0 0 -1" />
  </joint>
  <link name="fr_steering_link">
    <inertial>
      <origin xyz="4.41226727666E-05 -0.0157129719167314 0.00410410320602098" rpy="0 0 0" />
      <mass value="0.93530799163567" />
      <inertia ixx="0.00108568401565883" ixy="7.74351677124048E-08" ixz="2.33490054510254E-07" iyy="0.00106453940002428" iyz="0.000235815859378651" izz="0.0012538948846579" />
    </inertial>
    <visual>
      <origin xyz="0 0 0" rpy="0 0 0" />
      <geometry>
        <mesh filename="package://ranger_air_description/meshes/dae/fr_steering_link.dae" />
      </geometry>
      <material name="">
        <color rgba="0.752941176470588 0.752941176470588 0.752941176470588 1" />
      </material>
    </visual>
    <collision>
      <origin xyz="0 0 0" rpy="0 0 0" />
      <geometry>
        <mesh filename="package://ranger_air_description/meshes/dae/fr_steering_link.dae" />
      </geometry>
    </collision>
  </link>
  <joint name="fr_steering_joint" type="continuous">
    <origin xyz="0.194 -0.169 0.1355" rpy="3.14159265358979 0 0" />
    <parent link="base_link" />
    <child link="fr_steering_link" />
    <axis xyz="0 0 -1" />
  </joint>
  <link name="fr_wheel_link">
    <inertial>
      <origin xyz="2.77555756156289E-17 2.77555756156289E-17 0.000252801407574443" rpy="0 0 0" />
      <mass value="0.741126743204084" />
      <inertia ixx="0.000890769648192525" ixy="2.66918709362604E-24" ixz="2.16085103308491E-20" iyy="0.000890761023713874" iyz="6.4878824945206E-20" izz="0.00113190510709934" />
    </inertial>
    <visual>
      <origin xyz="0 0 0" rpy="0 0 0" />
      <geometry>
        <mesh filename="package://ranger_air_description/meshes/dae/fr_wheel_link.dae" />
      </geometry>
      <material name="">
        <color rgba="0.792156862745098 0.819607843137255 0.933333333333333 1" />
      </material>
    </visual>
    <collision>
      <origin xyz="0 0 0" rpy="0 0 0" />
      <geometry>
        <mesh filename="package://ranger_air_description/meshes/dae/fr_wheel_link.dae" />
      </geometry>
    </collision>
  </link>
  <joint name="fr_wheel_joint" type="continuous">
    <origin xyz="0 0 0.0749999999999999" rpy="1.5707963267949 0 0" />
    <parent link="fr_steering_link" />
    <child link="fr_wheel_link" />
    <axis xyz="0 0 -1" />
  </joint>
  <link name="rr_steering_link">
    <inertial>
      <origin xyz="4.41226716285104E-05 -0.0157129719156636 0.0041041032048897" rpy="0 0 0" />
      <mass value="0.935307991753156" />
      <inertia ixx="0.0010856840156653" ixy="7.74351596728921E-08" ixz="2.33490057369179E-07" iyy="0.00106453940003436" iyz="0.000235815859380944" izz="0.00125389488467438" />
    </inertial>
    <visual>
      <origin xyz="0 0 0" rpy="0 0 0" />
      <geometry>
        <mesh filename="package://ranger_air_description/meshes/dae/rr_steering_link.dae" />
      </geometry>
      <material name="">
        <color rgba="0.752941176470588 0.752941176470588 0.752941176470588 1" />
      </material>
    </visual>
    <collision>
      <origin xyz="0 0 0" rpy="0 0 0" />
      <geometry>
        <mesh filename="package://ranger_air_description/meshes/dae/rr_steering_link.dae" />
      </geometry>
    </collision>
  </link>
  <joint name="rr_steering_joint" type="continuous">
    <origin xyz="-0.194 -0.169 0.1365" rpy="3.14159265358979 0 0" />
    <parent link="base_link" />
    <child link="rr_steering_link" />
    <axis xyz="0 0 1" />
  </joint>
  <link name="rr_wheel_link">
    <inertial>
      <origin xyz="-2.77555756156289E-17 2.77555756156289E-17 0.000252801407574471" rpy="0 0 0" />
      <mass value="0.741126743204084" />
      <inertia ixx="0.000890769648192525" ixy="3.99267607366746E-24" ixz="2.79728229390156E-20" iyy="0.000890761023713874" iyz="6.48770386799988E-20" izz="0.00113190510709934" />
    </inertial>
    <visual>
      <origin xyz="0 0 0" rpy="0 0 0" />
      <geometry>
        <mesh filename="package://ranger_air_description/meshes/dae/rr_wheel_link.dae" />
      </geometry>
      <material name="">
        <color rgba="0.792156862745098 0.819607843137255 0.933333333333333 1" />
      </material>
    </visual>
    <collision>
      <origin xyz="0 0 0" rpy="0 0 0" />
      <geometry>
        <mesh filename="package://ranger_air_description/meshes/dae/rr_wheel_link.dae" />
      </geometry>
    </collision>
  </link>
  <joint name="rr_wheel_joint" type="continuous">
    <origin xyz="0 0 0.0749999999999999" rpy="1.5707963267949 0 0" />
    <parent link="rr_steering_link" />
    <child link="rr_wheel_link" />
    <axis xyz="0 0 -1" />
  </joint>
  <link name="rl_steering_link">
    <inertial>
      <origin xyz="-4.41226727664334E-05 0.0157129719167315 0.00410410320602111" rpy="0 0 0" />
      <mass value="0.935307991635669" />
      <inertia ixx="0.00108568401565883" ixy="7.74351677138188E-08" ixz="-2.3349005451069E-07" iyy="0.00106453940002428" iyz="-0.000235815859378651" izz="0.0012538948846579" />
    </inertial>
    <visual>
      <origin xyz="0 0 0" rpy="0 0 0" />
      <geometry>
        <mesh filename="package://ranger_air_description/meshes/dae/rl_steering_link.dae" />
      </geometry>
      <material name="">
        <color rgba="0.752941176470588 0.752941176470588 0.752941176470588 1" />
      </material>
    </visual>
    <collision>
      <origin xyz="0 0 0" rpy="0 0 0" />
      <geometry>
        <mesh filename="package://ranger_air_description/meshes/dae/rl_steering_link.dae" />
      </geometry>
    </collision>
  </link>
  <joint name="rl_steering_joint" type="continuous">
    <origin xyz="-0.194 0.169 0.1365" rpy="3.14159265358979 0 0" />
    <parent link="base_link" />
    <child link="rl_steering_link" />
    <axis xyz="0 0 -1" />
  </joint>
  <link name="rl_wheel_link">
    <inertial>
      <origin xyz="0 0 -0.000252801407574471" rpy="0 0 0" />
      <mass value="0.741126743204084" />
      <inertia ixx="0.000890769648192525" ixy="-4.04510352288153E-24" ixz="9.43709781956294E-21" iyy="0.000890761023713874" iyz="-1.30478774219597E-19" izz="0.00113190510709935" />
    </inertial>
    <visual>
      <origin xyz="0 0 0" rpy="0 0 0" />
      <geometry>
        <mesh filename="package://ranger_air_description/meshes/dae/rl_wheel_link.dae" />
      </geometry>
      <material name="">
        <color rgba="0.792156862745098 0.819607843137255 0.933333333333333 1" />
      </material>
    </visual>
    <collision>
      <origin xyz="0 0 0" rpy="0 0 0" />
      <geometry>
        <mesh filename="package://ranger_air_description/meshes/dae/rl_wheel_link.dae" />
      </geometry>
    </collision>
  </link>
  <joint name="rl_wheel_joint" type="continuous">
    <origin xyz="0 0 0.0749999999999999" rpy="1.5707963267949 0 0" />
    <parent link="rl_steering_link" />
    <child link="rl_wheel_link" />
    <axis xyz="0 0 1" />
  </joint>
  <link name="lift_base_link">
    <inertial>
      <origin xyz="0 0 0.05" rpy="0 0 0" />
      <mass value="8.0" />
      <inertia ixx="0.1" ixy="0" ixz="0" iyy="0.1" iyz="0" izz="0.1" />
    </inertial>
    <visual>
      <origin xyz="0 0 0" rpy="1.5707963267949 0 0" />
      <geometry>
        <mesh filename="package://ranger_air_description/meshes/linear_act_base.stl" />
      </geometry>
      <material name="lift_base_material">
        <color rgba="0.752941176470588 0.752941176470588 0.752941176470588 1" />
      </material>
    </visual>
    <collision>
      <origin xyz="0 0 0" rpy="1.5707963267949 0 0" />
      <geometry>
        <mesh filename="package://ranger_air_description/meshes/linear_act_base.stl" />
      </geometry>
    </collision>
  </link>
  <joint name="lift_base_joint" type="fixed">
    <origin xyz="0 0 0.28" rpy="0 0 0" />
    <parent link="base_link" />
    <child link="lift_base_link" />
  </joint>
  <link name="lift_link">
    <inertial>
      <origin xyz="-0.0175 0.2725 0.35" rpy="0 0 0" />
      <mass value="5.0" />
      <inertia ixx="0.05" ixy="0" ixz="0" iyy="0.05" iyz="0" izz="0.05" />
    </inertial>
    <visual>
      <origin xyz="0 -0.2 0" rpy="1.5707963267949 0 0" />
      <geometry>
        <mesh filename="package://ranger_air_description/meshes/linear_act_move.stl" />
      </geometry>
      <material name="lift_move_material">
        <color rgba="0.752941176470588 0.752941176470588 0.752941176470588 1" />
      </material>
    </visual>
    <collision>
      <origin xyz="0 -0.2 0" rpy="1.5707963267949 0 0" />
      <geometry>
        <mesh filename="package://ranger_air_description/meshes/linear_act_move.stl" />
      </geometry>
    </collision>
  </link>
  <joint name="lift_joint" type="prismatic">
    <origin xyz="0 0 0" rpy="0 0 0" />
    <parent link="lift_base_link" />
    <child link="lift_link" />
    <axis xyz="0 0 1" />
    <limit lower="0" upper="0.85" effort="500" velocity="0.25" />
  </joint>
  <joint name="openarm_mount_joint" type="fixed">
    <origin xyz="-0.0175 0.19 0.4" rpy="0 0 -1.5707963267949" />
    <parent link="lift_link" />
    <child link="openarm_body_link0" />
  </joint>
  <link name="openarm_body_link0">
    <visual name="openarm_body_link0_visual">
      <origin rpy="0.0 0.0 0.0" xyz="0.0 0.0 0.0" />
      <geometry>
        <mesh filename="package://openarm_description/assets/robot/openarm_v2.0/meshes/body/visual/body_link0.stl" />
      </geometry>
      <material name="openarm_body_link0_material">
        <color rgba="0.752941176470588 0.752941176470588 0.752941176470588 1" />
      </material>
    </visual>
    <collision name="openarm_body_link0_collision">
      <origin rpy="0.0 0.0 0.0" xyz="0.0 0.0 0.0" />
      <geometry>
        <mesh filename="package://openarm_description/assets/robot/openarm_v2.0/meshes/body/collision/body_link0_symp.stl" scale="0.001 0.001 0.001" />
      </geometry>
    </collision>
    <inertial>
      <origin rpy="0 0 0" xyz="0 0 0" />
      <mass value="13.89" />
      <inertia ixx="1.653" ixy="0.0" ixz="0.0" iyy="1.653" iyz="0.0" izz="0.051" />
    </inertial>
  </link>
  <link name="openarm_left_base_link">
    <visual name="openarm_left_base_link_visual">
      <origin rpy="0 0 0" xyz="0 0 0" />
      <geometry>
        <mesh filename="package://openarm_description/assets/robot/openarm_v2.0/meshes/arm/visual/base_link.dae" scale="1 -1 1" />
      </geometry>
      <material name="openarm_left_base_link_material">
        <color rgba="0.752941176470588 0.752941176470588 0.752941176470588 1" />
      </material>
    </visual>
    <collision name="openarm_left_base_link_collision">
      <origin rpy="0 0 0" xyz="0 0 0" />
      <geometry>
        <mesh filename="package://openarm_description/assets/robot/openarm_v2.0/meshes/arm/collision/base_link.stl" scale="1 -1 1" />
      </geometry>
    </collision>
    <inertial>
      <origin rpy="0 0 0" xyz="0.00253123748061566 0.0258185540330169 2.70658291858903e-05" />
      <mass value="1.1432284943239561" />
      <inertia ixx="0.00113607806226198" ixy="-3.81487993180929e-07" ixz="1.09161247709715e-08" iyy="0.00159935208714031" iyz="-2.7521421737084e-08" izz="0.000750541980863571" />
    </inertial>
  </link>
  <joint name="openarm_left_base_link_mount_joint" type="fixed">
    <origin rpy="0.0 0.0 0.0" xyz="0.0 0.031 0.698" />
    <parent link="openarm_body_link0" />
    <child link="openarm_left_base_link" />
  </joint>
  <link name="openarm_left_link1">
    <visual name="openarm_left_link1_visual">
      <origin rpy="0 0 0" xyz="0 0 0" />
      <geometry>
        <mesh filename="package://openarm_description/assets/robot/openarm_v2.0/meshes/arm/visual/link1.dae" scale="1 -1 1" />
      </geometry>
      <material name="openarm_left_link1_material">
        <color rgba="0.752941176470588 0.752941176470588 0.752941176470588 1" />
      </material>
    </visual>
    <collision name="openarm_left_link1_collision">
      <origin rpy="0 0 0" xyz="0 0 0" />
      <geometry>
        <mesh filename="package://openarm_description/assets/robot/openarm_v2.0/meshes/arm/collision/link1.stl" scale="1 -1 1" />
      </geometry>
    </collision>
    <inertial>
      <origin rpy="0 0 0" xyz="0.000900350355624244 0.0444659716892874 2.88441021165683e-05" />
      <mass value="1.1416684646202298" />
      <inertia ixx="0.0010943212038551" ixy="-9.41628673674543e-06" ixz="4.53422182483102e-08" iyy="0.000759199728161993" iyz="-6.66755698859637e-08" izz="0.000670659201019629" />
    </inertial>
  </link>
  <joint name="openarm_left_joint1" type="revolute">
    <origin rpy="0 0 0" xyz="0 0.0625 0" />
    <parent link="openarm_left_base_link" />
    <child link="openarm_left_link1" />
    <axis xyz="0 1 0" />
    <limit effort="40" lower="-3.4907" upper="1.3963" velocity="16.755" />
  </joint>
  <link name="openarm_left_link2">
    <visual name="openarm_left_link2_visual">
      <origin rpy="0 0 0" xyz="0 0 0" />
      <geometry>
        <mesh filename="package://openarm_description/assets/robot/openarm_v2.0/meshes/arm/visual/link2.dae" scale="1 -1 1" />
      </geometry>
      <material name="openarm_left_link2_material">
        <color rgba="0.752941176470588 0.752941176470588 0.752941176470588 1" />
      </material>
    </visual>
    <collision name="openarm_left_link2_collision">
      <origin rpy="0 0 0" xyz="0 0 0" />
      <geometry>
        <mesh filename="package://openarm_description/assets/robot/openarm_v2.0/meshes/arm/collision/link2.stl" scale="1 -1 1" />
      </geometry>
    </collision>
    <inertial>
      <origin rpy="0 0 0" xyz="-0.0247184924346635 -7.60578399428002e-08 -0.0312643102292087" />
      <mass value="0.2775092746011571" />
      <inertia ixx="0.000153588833784759" ixy="2.94422592188677e-10" ixz="5.21056076779068e-06" iyy="0.000113062180225725" iyz="-3.75816911469744e-10" izz="8.22999351863579e-05" />
    </inertial>
  </link>
  <joint name="openarm_left_joint2" type="revolute">
    <origin rpy="0 0 0" xyz="0 0.0600000000000001 0" />
    <parent link="openarm_left_link1" />
    <child link="openarm_left_link2" />
    <axis xyz="-1 0 0" />
    <limit effort="40" lower="-3.3161" upper="0.17453" velocity="16.755" />
  </joint>
  <link name="openarm_left_link3">
    <visual name="openarm_left_link3_visual">
      <origin rpy="0 0 0" xyz="0 0 0" />
      <geometry>
        <mesh filename="package://openarm_description/assets/robot/openarm_v2.0/meshes/arm/visual/link3.dae" scale="1 1 1" />
      </geometry>
      <material name="openarm_left_link3_material">
        <color rgba="0.752941176470588 0.752941176470588 0.752941176470588 1" />
      </material>
    </visual>
    <collision name="openarm_left_link3_collision">
      <origin rpy="0 0 0" xyz="0 0 0" />
      <geometry>
        <mesh filename="package://openarm_description/assets/robot/openarm_v2.0/meshes/arm/collision/link3.stl" scale="1 1 1" />
      </geometry>
    </collision>
    <inertial>
      <origin rpy="0 0 0" xyz="-0.00300861804638783 -0.000514813312550808 -0.109368241429434" />
      <mass value="1.073863338202347" />
      <inertia ixx="0.00128939636591746" ixy="-2.29951046666492e-07" ixz="-6.76161926984358e-05" iyy="0.00114018992179734" iyz="-1.06260802872572e-05" izz="0.000559765478676303" />
    </inertial>
  </link>
  <joint name="openarm_left_joint3" type="revolute">
    <origin rpy="0 0 0" xyz="0 0 -0.0662500000000008" />
    <parent link="openarm_left_link2" />
    <child link="openarm_left_link3" />
    <axis xyz="0 0 -1" />
    <limit effort="27" lower="-1.5708" upper="1.5708" velocity="5.4454" />
  </joint>
  <link name="openarm_left_link4">
    <visual name="openarm_left_link4_visual">
      <origin rpy="0 0 0" xyz="0 0 0" />
      <geometry>
        <mesh filename="package://openarm_description/assets/robot/openarm_v2.0/meshes/arm/visual/link4.dae" scale="1 1 1" />
      </geometry>
      <material name="openarm_left_link4_material">
        <color rgba="0.752941176470588 0.752941176470588 0.752941176470588 1" />
      </material>
    </visual>
    <collision name="openarm_left_link4_collision">
      <origin rpy="0 0 0" xyz="0 0 0" />
      <geometry>
        <mesh filename="package://openarm_description/assets/robot/openarm_v2.0/meshes/arm/collision/link4.stl" scale="1 1 1" />
      </geometry>
    </collision>
    <inertial>
      <origin rpy="0 0 0" xyz="-0.00310326243752606 -0.00136538979048502 -0.0574601379354351" />
      <mass value="0.6348534566833373" />
      <inertia ixx="0.0004690036047182" ixy="5.63626910265645e-06" ixz="-1.77877991597693e-06" iyy="0.000433926270522842" iyz="3.41757797773822e-06" izz="0.000245211429759716" />
    </inertial>
  </link>
  <joint name="openarm_left_joint4" type="revolute">
    <origin rpy="0 0 0" xyz="0 0 -0.15375" />
    <parent link="openarm_left_link3" />
    <child link="openarm_left_link4" />
    <axis xyz="0 -1 0" />
    <limit effort="27" lower="0" upper="2.4435" velocity="5.4454" />
  </joint>
  <link name="openarm_left_link5">
    <visual name="openarm_left_link5_visual">
      <origin rpy="0 0 0" xyz="0 0 0" />
      <geometry>
        <mesh filename="package://openarm_description/assets/robot/openarm_v2.0/meshes/arm/visual/link5.dae" scale="1 -1 1" />
      </geometry>
      <material name="openarm_left_link5_material">
        <color rgba="0.752941176470588 0.752941176470588 0.752941176470588 1" />
      </material>
    </visual>
    <collision name="openarm_left_link5_collision">
      <origin rpy="0 0 0" xyz="0 0 0" />
      <geometry>
        <mesh filename="package://openarm_description/assets/robot/openarm_v2.0/meshes/arm/collision/link5.stl" scale="1 -1 1" />
      </geometry>
    </collision>
    <inertial>
      <origin rpy="0 0 0" xyz="-0.000737188580130584 0.000412406544351845 -0.047093829077211" />
      <mass value="0.6156588026168502" />
      <inertia ixx="0.000279653368752989" ixy="-3.31745289972445e-06" ixz="7.68097311403736e-07" iyy="0.000334599623120095" iyz="1.49934409279756e-07" izz="0.000176662464388138" />
    </inertial>
  </link>
  <joint name="openarm_left_joint5" type="revolute">
    <origin rpy="0 0 0" xyz="0 0 -0.0955000000000005" />
    <parent link="openarm_left_link4" />
    <child link="openarm_left_link5" />
    <axis xyz="0 0 -1" />
    <limit effort="7" lower="-1.5708" upper="1.5708" velocity="20.944" />
  </joint>
  <link name="openarm_left_link6">
    <visual name="openarm_left_link6_visual">
      <origin rpy="0 0 0" xyz="0 0 0" />
      <geometry>
        <mesh filename="package://openarm_description/assets/robot/openarm_v2.0/meshes/arm/visual/link6.dae" scale="1 -1 1" />
      </geometry>
      <material name="openarm_left_link6_material">
        <color rgba="0.752941176470588 0.752941176470588 0.752941176470588 1" />
      </material>
    </visual>
    <collision name="openarm_left_link6_collision">
      <origin rpy="0 0 0" xyz="0 0 0" />
      <geometry>
        <mesh filename="package://openarm_description/assets/robot/openarm_v2.0/meshes/arm/collision/link6.stl" scale="1 -1 1" />
      </geometry>
    </collision>
    <inertial>
      <origin rpy="0 0 0" xyz="2.27438423593244e-05 -0.00068649602098908 5.44000494765995e-05" />
      <mass value="0.475202773187987" />
      <inertia ixx="0.000179275941446964" ixy="-6.58439346712228e-08" ixz="-3.37101167120887e-08" iyy="0.000136247512758587" iyz="-3.32253600295544e-08" izz="0.000135340695937386" />
    </inertial>
  </link>
  <joint name="openarm_left_joint6" type="revolute">
    <origin rpy="0 0 0" xyz="0 0 -0.120499999999998" />
    <parent link="openarm_left_link5" />
    <child link="openarm_left_link6" />
    <axis xyz="0 -1 0" />
    <limit effort="7" lower="-0.7854" upper="0.7854" velocity="20.944" />
  </joint>
  <joint name="openarm_left_joint7" type="revolute">
    <origin rpy="0 0 0" xyz="0 0 0" />
    <parent link="openarm_left_link6" />
    <child link="openarm_left_ee_base_link" />
    <axis xyz="1 0 0" />
    <limit effort="7" lower="-1.5708" upper="1.5708" velocity="20.944" />
  </joint>
  <link name="openarm_left_ee_base_link">
    <visual name="openarm_left_ee_base_link_visual">
      <origin rpy="0.0 -0.0 0.0" xyz="0.0205 -0.0 0.0" />
      <geometry>
        <mesh filename="package://openarm_description/assets/end_effector/pinch_gripper/meshes/visual/ee_base_link.dae" scale="1 -1 1" />
      </geometry>
      <material name="openarm_left_ee_base_link_material">
        <color rgba="0.752941176470588 0.752941176470588 0.752941176470588 1" />
      </material>
    </visual>
    <collision name="openarm_left_ee_base_link_collision">
      <origin rpy="0.0 -0.0 0.0" xyz="0.0205 -0.0 0.0" />
      <geometry>
        <mesh filename="package://openarm_description/assets/end_effector/pinch_gripper/meshes/collision/ee_base_link.stl" scale="1 -1 1" />
      </geometry>
    </collision>
    <inertial>
      <origin rpy="0.0 -0.0 0.0" xyz="0.0137902 -0.0084073 -0.05938" />
      <mass value="0.52832" />
      <inertia ixx="0.00021911" ixy="-4.1683e-06" ixz="1.4043e-06" iyy="0.00015627" iyz="1.5124e-06" izz="0.0001659" />
    </inertial>
  </link>
  <link name="openarm_left_ee_link1">
    <visual name="openarm_left_ee_link1_visual">
      <origin rpy="0 0 0" xyz="0 0 0" />
      <geometry>
        <mesh filename="package://openarm_description/assets/end_effector/pinch_gripper/meshes/visual/finger_inner.dae" scale="1 -1 1" />
      </geometry>
      <material name="openarm_left_ee_link1_material">
        <color rgba="0.752941176470588 0.752941176470588 0.752941176470588 1" />
      </material>
    </visual>
    <collision name="openarm_left_ee_link1_collision">
      <origin rpy="0 0 0" xyz="0 0 0" />
      <geometry>
        <mesh filename="package://openarm_description/assets/end_effector/pinch_gripper/meshes/collision/finger_inner.stl" scale="1 -1 1" />
      </geometry>
    </collision>
    <inertial>
      <origin rpy="0 0 0" xyz="-0.0124990911725494 -0.00176592789915655 -0.0241663193888537" />
      <mass value="0.125979047366671" />
      <inertia ixx="3.61105363396623e-05" ixy="-1.35880208293387e-06" ixz="7.13916341634141e-06" iyy="3.62137424319396e-05" iyz="3.60343788693423e-06" izz="1.74958961632907e-05" />
    </inertial>
  </link>
  <link name="openarm_left_ee_link2">
    <visual name="openarm_left_ee_link2_visual">
      <origin rpy="0 0 0" xyz="0 0 0" />
      <geometry>
        <mesh filename="package://openarm_description/assets/end_effector/pinch_gripper/meshes/visual/finger_outer.dae" scale="1 -1 1" />
      </geometry>
      <material name="openarm_left_ee_link2_material">
        <color rgba="0.752941176470588 0.752941176470588 0.752941176470588 1" />
      </material>
    </visual>
    <collision name="openarm_left_ee_link2_collision">
      <origin rpy="0 0 0" xyz="0 0 0" />
      <geometry>
        <mesh filename="package://openarm_description/assets/end_effector/pinch_gripper/meshes/collision/finger_outer.stl" scale="1 -1 1" />
      </geometry>
    </collision>
    <inertial>
      <origin rpy="0 0 0" xyz="-0.012796 0.0020183 -0.026792" />
      <mass value="0.11372" />
      <inertia ixx="3.4565e-05" ixy="1.3392e-06" ixz="7.1576e-06" iyy="3.5306e-05" iyz="-3.7172e-06" izz="1.6571e-05" />
    </inertial>
  </link>
  <joint name="openarm_left_finger_joint1" type="revolute">
    <origin rpy="0.0 -0.0 0.0" xyz="-0.0014300000000005003 -0.0180000000000009 -0.0680000000000174" />
    <parent link="openarm_left_ee_base_link" />
    <child link="openarm_left_ee_link1" />
    <axis xyz="-1 0 0" />
    <limit effort="7" lower="0" upper="0.7854" velocity="5" />
  </joint>
  <joint name="openarm_left_finger_joint2" type="revolute">
    <origin rpy="0.0 -0.0 0.0" xyz="-0.0014300000000005003 0.0180000000000012 -0.0680000000000215" />
    <parent link="openarm_left_ee_base_link" />
    <child link="openarm_left_ee_link2" />
    <axis xyz="1 0 0" />
    <limit effort="7" lower="0" upper="0.7854" velocity="5" />
    <mimic joint="openarm_left_finger_joint1" multiplier="1" offset="0" />
  </joint>
  <link name="openarm_right_base_link">
    <visual name="openarm_right_base_link_visual">
      <origin rpy="0 0 0" xyz="0 0 0" />
      <geometry>
        <mesh filename="package://openarm_description/assets/robot/openarm_v2.0/meshes/arm/visual/base_link.dae" scale="1 1 1" />
      </geometry>
      <material name="openarm_right_base_link_material">
        <color rgba="0.752941176470588 0.752941176470588 0.752941176470588 1" />
      </material>
    </visual>
    <collision name="openarm_right_base_link_collision">
      <origin rpy="0 0 0" xyz="0 0 0" />
      <geometry>
        <mesh filename="package://openarm_description/assets/robot/openarm_v2.0/meshes/arm/collision/base_link.stl" scale="1 1 1" />
      </geometry>
    </collision>
    <inertial>
      <origin rpy="0 0 0" xyz="0.00253123748061566 -0.0258185540330169 2.70658291858903e-05" />
      <mass value="1.1432284943239561" />
      <inertia ixx="0.00113607806226198" ixy="3.81487993180929e-07" ixz="1.09161247709715e-08" iyy="0.00159935208714031" iyz="2.7521421737084e-08" izz="0.000750541980863571" />
    </inertial>
  </link>
  <joint name="openarm_right_base_link_mount_joint" type="fixed">
    <origin rpy="0.0 0.0 0.0" xyz="0.0 -0.031 0.698" />
    <parent link="openarm_body_link0" />
    <child link="openarm_right_base_link" />
  </joint>
  <link name="openarm_right_link1">
    <visual name="openarm_right_link1_visual">
      <origin rpy="0 0 0" xyz="0 0 0" />
      <geometry>
        <mesh filename="package://openarm_description/assets/robot/openarm_v2.0/meshes/arm/visual/link1.dae" scale="1 1 1" />
      </geometry>
      <material name="openarm_right_link1_material">
        <color rgba="0.752941176470588 0.752941176470588 0.752941176470588 1" />
      </material>
    </visual>
    <collision name="openarm_right_link1_collision">
      <origin rpy="0 0 0" xyz="0 0 0" />
      <geometry>
        <mesh filename="package://openarm_description/assets/robot/openarm_v2.0/meshes/arm/collision/link1.stl" scale="1 1 1" />
      </geometry>
    </collision>
    <inertial>
      <origin rpy="0 0 0" xyz="0.000900350355624244 -0.0444659716892874 2.88441021165683e-05" />
      <mass value="1.1416684646202298" />
      <inertia ixx="0.0010943212038551" ixy="9.41628673674543e-06" ixz="4.53422182483102e-08" iyy="0.000759199728161993" iyz="6.66755698859637e-08" izz="0.000670659201019629" />
    </inertial>
  </link>
  <joint name="openarm_right_joint1" type="revolute">
    <origin rpy="0 0 0" xyz="0 -0.0625 0" />
    <parent link="openarm_right_base_link" />
    <child link="openarm_right_link1" />
    <axis xyz="0 -1 0" />
    <limit effort="40" lower="-1.3963" upper="3.4907" velocity="16.755" />
  </joint>
  <link name="openarm_right_link2">
    <visual name="openarm_right_link2_visual">
      <origin rpy="0 0 0" xyz="0 0 0" />
      <geometry>
        <mesh filename="package://openarm_description/assets/robot/openarm_v2.0/meshes/arm/visual/link2.dae" scale="1 1 1" />
      </geometry>
      <material name="openarm_right_link2_material">
        <color rgba="0.752941176470588 0.752941176470588 0.752941176470588 1" />
      </material>
    </visual>
    <collision name="openarm_right_link2_collision">
      <origin rpy="0 0 0" xyz="0 0 0" />
      <geometry>
        <mesh filename="package://openarm_description/assets/robot/openarm_v2.0/meshes/arm/collision/link2.stl" scale="1 1 1" />
      </geometry>
    </collision>
    <inertial>
      <origin rpy="0 0 0" xyz="-0.0247184924346635 7.60578399428002e-08 -0.0312643102292087" />
      <mass value="0.2775092746011571" />
      <inertia ixx="0.000153588833784759" ixy="-2.94422592188677e-10" ixz="5.21056076779068e-06" iyy="0.000113062180225725" iyz="3.75816911469744e-10" izz="8.22999351863579e-05" />
    </inertial>
  </link>
  <joint name="openarm_right_joint2" type="revolute">
    <origin rpy="0 0 0" xyz="0 -0.0600000000000001 0" />
    <parent link="openarm_right_link1" />
    <child link="openarm_right_link2" />
    <axis xyz="-1 0 0" />
    <limit effort="40" lower="-0.17453" upper="3.3161" velocity="16.755" />
  </joint>
  <link name="openarm_right_link3">
    <visual name="openarm_right_link3_visual">
      <origin rpy="0 0 0" xyz="0 0 0" />
      <geometry>
        <mesh filename="package://openarm_description/assets/robot/openarm_v2.0/meshes/arm/visual/link3.dae" scale="1 1 1" />
      </geometry>
      <material name="openarm_right_link3_material">
        <color rgba="0.752941176470588 0.752941176470588 0.752941176470588 1" />
      </material>
    </visual>
    <collision name="openarm_right_link3_collision">
      <origin rpy="0 0 0" xyz="0 0 0" />
      <geometry>
        <mesh filename="package://openarm_description/assets/robot/openarm_v2.0/meshes/arm/collision/link3.stl" scale="1 1 1" />
      </geometry>
    </collision>
    <inertial>
      <origin rpy="0 0 0" xyz="-0.00300861804638783 -0.000514813312550808 -0.109368241429434" />
      <mass value="1.073863338202347" />
      <inertia ixx="0.00128939636591746" ixy="-2.29951046666492e-07" ixz="-6.76161926984358e-05" iyy="0.00114018992179734" iyz="-1.06260802872572e-05" izz="0.000559765478676303" />
    </inertial>
  </link>
  <joint name="openarm_right_joint3" type="revolute">
    <origin rpy="0 0 0" xyz="0 0 -0.0662500000000008" />
    <parent link="openarm_right_link2" />
    <child link="openarm_right_link3" />
    <axis xyz="0 0 -1" />
    <limit effort="27" lower="-1.5708" upper="1.5708" velocity="5.4454" />
  </joint>
  <link name="openarm_right_link4">
    <visual name="openarm_right_link4_visual">
      <origin rpy="0 0 0" xyz="0 0 0" />
      <geometry>
        <mesh filename="package://openarm_description/assets/robot/openarm_v2.0/meshes/arm/visual/link4.dae" scale="1 1 1" />
      </geometry>
      <material name="openarm_right_link4_material">
        <color rgba="0.752941176470588 0.752941176470588 0.752941176470588 1" />
      </material>
    </visual>
    <collision name="openarm_right_link4_collision">
      <origin rpy="0 0 0" xyz="0 0 0" />
      <geometry>
        <mesh filename="package://openarm_description/assets/robot/openarm_v2.0/meshes/arm/collision/link4.stl" scale="1 1 1" />
      </geometry>
    </collision>
    <inertial>
      <origin rpy="0 0 0" xyz="-0.00310326243752606 -0.00136538979048502 -0.0574601379354351" />
      <mass value="0.6348534566833373" />
      <inertia ixx="0.0004690036047182" ixy="5.63626910265645e-06" ixz="-1.77877991597693e-06" iyy="0.000433926270522842" iyz="3.41757797773822e-06" izz="0.000245211429759716" />
    </inertial>
  </link>
  <joint name="openarm_right_joint4" type="revolute">
    <origin rpy="0 0 0" xyz="0 0 -0.15375" />
    <parent link="openarm_right_link3" />
    <child link="openarm_right_link4" />
    <axis xyz="0 -1 0" />
    <limit effort="27" lower="0" upper="2.4435" velocity="5.4454" />
  </joint>
  <link name="openarm_right_link5">
    <visual name="openarm_right_link5_visual">
      <origin rpy="0 0 0" xyz="0 0 0" />
      <geometry>
        <mesh filename="package://openarm_description/assets/robot/openarm_v2.0/meshes/arm/visual/link5.dae" scale="1 1 1" />
      </geometry>
      <material name="openarm_right_link5_material">
        <color rgba="0.752941176470588 0.752941176470588 0.752941176470588 1" />
      </material>
    </visual>
    <collision name="openarm_right_link5_collision">
      <origin rpy="0 0 0" xyz="0 0 0" />
      <geometry>
        <mesh filename="package://openarm_description/assets/robot/openarm_v2.0/meshes/arm/collision/link5.stl" scale="1 1 1" />
      </geometry>
    </collision>
    <inertial>
      <origin rpy="0 0 0" xyz="-0.000737188580130584 -0.000412406544351845 -0.047093829077211" />
      <mass value="0.6156588026168502" />
      <inertia ixx="0.000279653368752989" ixy="3.31745289972445e-06" ixz="7.68097311403736e-07" iyy="0.000334599623120095" iyz="-1.49934409279756e-07" izz="0.000176662464388138" />
    </inertial>
  </link>
  <joint name="openarm_right_joint5" type="revolute">
    <origin rpy="0 0 0" xyz="0 0 -0.0955000000000005" />
    <parent link="openarm_right_link4" />
    <child link="openarm_right_link5" />
    <axis xyz="0 0 -1" />
    <limit effort="7" lower="-1.5708" upper="1.5708" velocity="20.944" />
  </joint>
  <link name="openarm_right_link6">
    <visual name="openarm_right_link6_visual">
      <origin rpy="0 0 0" xyz="0 0 0" />
      <geometry>
        <mesh filename="package://openarm_description/assets/robot/openarm_v2.0/meshes/arm/visual/link6.dae" scale="1 1 1" />
      </geometry>
      <material name="openarm_right_link6_material">
        <color rgba="0.752941176470588 0.752941176470588 0.752941176470588 1" />
      </material>
    </visual>
    <collision name="openarm_right_link6_collision">
      <origin rpy="0 0 0" xyz="0 0 0" />
      <geometry>
        <mesh filename="package://openarm_description/assets/robot/openarm_v2.0/meshes/arm/collision/link6.stl" scale="1 1 1" />
      </geometry>
    </collision>
    <inertial>
      <origin rpy="0 0 0" xyz="2.27438423593244e-05 0.00068649602098908 5.44000494765995e-05" />
      <mass value="0.475202773187987" />
      <inertia ixx="0.000179275941446964" ixy="6.58439346712228e-08" ixz="-3.37101167120887e-08" iyy="0.000136247512758587" iyz="3.32253600295544e-08" izz="0.000135340695937386" />
    </inertial>
  </link>
  <joint name="openarm_right_joint6" type="revolute">
    <origin rpy="0 0 0" xyz="0 0 -0.120499999999998" />
    <parent link="openarm_right_link5" />
    <child link="openarm_right_link6" />
    <axis xyz="0 1 0" />
    <limit effort="7" lower="-0.7854" upper="0.7854" velocity="20.944" />
  </joint>
  <joint name="openarm_right_joint7" type="revolute">
    <origin rpy="0 0 0" xyz="0 0 0" />
    <parent link="openarm_right_link6" />
    <child link="openarm_right_ee_base_link" />
    <axis xyz="1 0 0" />
    <limit effort="7" lower="-1.5708" upper="1.5708" velocity="20.944" />
  </joint>
  <link name="openarm_right_ee_base_link">
    <visual name="openarm_right_ee_base_link_visual">
      <origin rpy="0.0 -0.0 0.0" xyz="0.0205 0.0 0.0" />
      <geometry>
        <mesh filename="package://openarm_description/assets/end_effector/pinch_gripper/meshes/visual/ee_base_link.dae" scale="1 1 1" />
      </geometry>
      <material name="openarm_right_ee_base_link_material">
        <color rgba="0.752941176470588 0.752941176470588 0.752941176470588 1" />
      </material>
    </visual>
    <collision name="openarm_right_ee_base_link_collision">
      <origin rpy="0.0 -0.0 0.0" xyz="0.0205 0.0 0.0" />
      <geometry>
        <mesh filename="package://openarm_description/assets/end_effector/pinch_gripper/meshes/collision/ee_base_link.stl" scale="1 1 1" />
      </geometry>
    </collision>
    <inertial>
      <origin rpy="0.0 -0.0 0.0" xyz="0.0137902 0.0084073 -0.05938" />
      <mass value="0.52832" />
      <inertia ixx="0.00021911" ixy="4.1683e-06" ixz="1.4043e-06" iyy="0.00015627" iyz="-1.5124e-06" izz="0.0001659" />
    </inertial>
  </link>
  <link name="openarm_right_ee_link1">
    <visual name="openarm_right_ee_link1_visual">
      <origin rpy="0 0 0" xyz="0 0 0" />
      <geometry>
        <mesh filename="package://openarm_description/assets/end_effector/pinch_gripper/meshes/visual/finger_inner.dae" scale="1 1 1" />
      </geometry>
      <material name="openarm_right_ee_link1_material">
        <color rgba="0.752941176470588 0.752941176470588 0.752941176470588 1" />
      </material>
    </visual>
    <collision name="openarm_right_ee_link1_collision">
      <origin rpy="0 0 0" xyz="0 0 0" />
      <geometry>
        <mesh filename="package://openarm_description/assets/end_effector/pinch_gripper/meshes/collision/finger_inner.stl" scale="1 1 1" />
      </geometry>
    </collision>
    <inertial>
      <origin rpy="0 0 0" xyz="-0.0124990911725494 0.00176592789915655 -0.0241663193888537" />
      <mass value="0.125979047366671" />
      <inertia ixx="3.61105363396623e-05" ixy="1.35880208293387e-06" ixz="7.13916341634141e-06" iyy="3.62137424319396e-05" iyz="-3.60343788693423e-06" izz="1.74958961632907e-05" />
    </inertial>
  </link>
  <link name="openarm_right_ee_link2">
    <visual name="openarm_right_ee_link2_visual">
      <origin rpy="0 0 0" xyz="0 0 0" />
      <geometry>
        <mesh filename="package://openarm_description/assets/end_effector/pinch_gripper/meshes/visual/finger_outer.dae" scale="1 1 1" />
      </geometry>
      <material name="openarm_right_ee_link2_material">
        <color rgba="0.752941176470588 0.752941176470588 0.752941176470588 1" />
      </material>
    </visual>
    <collision name="openarm_right_ee_link2_collision">
      <origin rpy="0 0 0" xyz="0 0 0" />
      <geometry>
        <mesh filename="package://openarm_description/assets/end_effector/pinch_gripper/meshes/collision/finger_outer.stl" scale="1 1 1" />
      </geometry>
    </collision>
    <inertial>
      <origin rpy="0 0 0" xyz="-0.012796 -0.0020183 -0.026792" />
      <mass value="0.11372" />
      <inertia ixx="3.4565e-05" ixy="-1.3392e-06" ixz="7.1576e-06" iyy="3.5306e-05" iyz="3.7172e-06" izz="1.6571e-05" />
    </inertial>
  </link>
  <joint name="openarm_right_finger_joint1" type="revolute">
    <origin rpy="0.0 -0.0 0.0" xyz="-0.0014300000000005003 0.0180000000000009 -0.0680000000000174" />
    <parent link="openarm_right_ee_base_link" />
    <child link="openarm_right_ee_link1" />
    <axis xyz="-1 0 0" />
    <limit effort="7" lower="-0.7854" upper="0" velocity="5" />
  </joint>
  <joint name="openarm_right_finger_joint2" type="revolute">
    <origin rpy="0.0 -0.0 0.0" xyz="-0.0014300000000005003 -0.0180000000000012 -0.0680000000000215" />
    <parent link="openarm_right_ee_base_link" />
    <child link="openarm_right_ee_link2" />
    <axis xyz="1 0 0" />
    <limit effort="7" lower="-0.7854" upper="0" velocity="5" />
    <mimic joint="openarm_right_finger_joint1" multiplier="1" offset="0" />
  </joint>
</robot>